<?xml version="1.0"?>
<robot name="mobile_robot">
    <link name="base_link">
        <inertial>
            <origin xyz="0 0 0.1"/>
            <mass value="5.0"/>
            <inertia 
                    ixx="0.1" ixy="0" ixz="0"
                    iyy="0.1" iyz="0"
                    izz="0.1"/>
        </inertial>
        <visual>
            <origin xyz="0 0 0.1"/>
            <geometry>
                <box size="0.4 0.3 0.1"/>
            </geometry>
        </visual>

        <collision>
            <origin xyz="0 0 0.1"/> 
            <geometry>
                <box size="0.4 0.3 0.1"/>
            </geometry>
        </collision>
    </link>

    <link name="left_wheel">
        <inertial>
            <origin xyz="0 0 0"/>
            <mass value="0.5"/>
            <inertia 
                    ixx="0.001" ixy="0" ixz="0"
                    iyy="0.001" iyz="0"
                    izz="0.001"/>
        </inertial>
        <visual>
            <origin xyz="0 0 0" rpy="1.5708 0 0"/>
            <geometry>
                <cylinder radius="0.05" length="0.02"/>
            </geometry>
        </visual>

        <collision>
            <origin xyz="0 0 0" rpy="1.5708 0 0"/>
            <geometry>
                <cylinder radius="0.05" length="0.02"/>
            </geometry>
            <surface>
                <friction>
                    <ode>
                        <mu>1.2</mu>
                        <mu2>1.2</mu2>
                    </ode>
                </friction>
            </surface>
        </collision>
    </link>

    <link name="right_wheel">
        <inertial>
            <origin xyz="0 0 0"/>
            <mass value="0.5"/>
            <inertia 
                    ixx="0.001" ixy="0" ixz="0"
                    iyy="0.001" iyz="0"
                    izz="0.001"/>
        </inertial>
        <visual>
            <origin xyz="0 0 0" rpy="1.5708 0 0"/>
            <geometry>
                <cylinder radius="0.05" length="0.02"/>
            </geometry>
        </visual>

        <collision>
            <origin xyz="0 0 0" rpy="1.5708 0 0"/>
            <geometry>
                <cylinder radius="0.05" length="0.02"/>
            </geometry>
            <surface>
                <friction>
                    <ode>
                        <mu>1.2</mu>
                        <mu2>1.2</mu2>
                    </ode>
                </friction>
            </surface>
        </collision>
    </link>

    <joint name="left_wheel_joint" type="continuous">
        <parent link="base_link"/>
        <child link="left_wheel"/>
        <origin xyz="0 -0.15 0.05" rpy="0 0 0"/>
        <axis xyz="0 1 0"/>
    </joint>
    <joint name="right_wheel_joint" type="continuous">
        <parent link="base_link"/>
        <child link="right_wheel"/>
        <origin xyz="0 0.15 0.05" rpy="0 0 0"/>
        <axis xyz="0 1 0"/>
    </joint>

    <link name="camera_link">
        <visual>
            <geometry>
                <box size="0.05 0.05 0.03"/>
            </geometry>
        </visual>
        <collision>
            <geometry>
                <box size="0.05 0.05 0.03"/>
            </geometry>
        </collision>
        <inertial>
            <mass value="0.1"/>
            <inertia
                    ixx="0.0001" ixy="0" ixz="0"
                    iyy="0.0001" iyz="0"
                    izz="0.0001"/>
        </inertial>
    </link>

    <joint name="camera_joint" type="fixed">
        <parent link="base_link"/>
        <child link="camera_link"/>
        <origin xyz="0.15 0 0.15" rpy="0 0 0"/>
    </joint>

    <gazebo>
        <plugin filename="libgz-sim8-diff-drive-system.so" name="gz::sim::systems::DiffDrive">
            <left_joint>left_wheel_joint</left_joint>
            <right_joint>right_wheel_joint</right_joint>
            <wheel_separation>0.30</wheel_separation>
            <wheel_radius>0.05</wheel_radius>
            <odom_topic>/odom</odom_topic>
            <odom_frame>odom</odom_frame>
            <base_frame>base_link</base_frame>
            <topic>cmd_vel</topic>
        </plugin>
    </gazebo>
</robot>